Workbook
Name Active_Employees: HR_SUMMARY!$B$3
Name Attrition_Rate: HR_SUMMARY!$B$5
Name Slicer_Department: #N/A
Name Slicer_Gender: #N/A
Name Slicer_Location: #N/A
Name Total_Employees: HR_SUMMARY!$B$2

Sheet RAW_DATA
A1: Employee_ID | B1: Employee_Name | C1: Department | D1: Location | E1: Job_Title | F1: Gender | G1: Age | H1: Education | I1: Employment_Status | J1: Joining_Date | K1: Experience_Years | L1: Annual_Salary | M1: Bonus_Percent | N1: Performance_Rating | O1: Attrition | P1: Phone | Q1: Email | R1: Overtime_Hours | S1: Training_Hours | T1: Manager_ID
A2: EMP1493 | B2: Yash Gupta | C2: Human Resources | D2: Bangalore | E2: Senior Manager | F2: M | G2: 24 | H2: M.Tech | I2: Contract | J2: 2023-05-13 | K2: 2.4 | L2: 1939110 | M2: 17.68 | N2: 4 | O2: yes | P2: +91-8389763738 | Q2: yash.gupta42@company.com | R2: 72 | S2: 23 | T2: EMP1001
A3: EMP1215 | B3: Manish Iyer | C3: sales | D3: Bangalore | E3: Senior Consultant | F3: Female | G3: 52 | H3: MBA | I3: Active | J3: 2019-01-16 | K3: 1.5 | L3: 478328 | M3: 22.53 | N3: 5 | O3: No | Q3: manish.iyer78@company.com | S3: 18 | T3: EMP1096
A4: EMP1262 | B4: Shruti Bhat | C4: Finance | D4: New Delhi | E4: Intern | F4: F | G4: 22 | H4: BBA | I4: On Leave | J4: 2023-01-14 | K4: 15.5 | L4: 906497 | M4: 17.3 | N4: 4 | O4: No | P4: +91-7293791975 | Q4: shruti.bhat86@company.com | R4: 42 | S4: 72 | T4: EMP1043
A5: EMP1368 | B5: Nitin Banerjee | C5: Operations | D5: mumbai | E5: Director | F5: male | G5: 39 | H5: Diploma | I5: On Leave | J5: 2024-01-14 | K5: 2.7 | L5: 2451024 | M5: 6.15 | N5: 4 | O5: Y | P5: +91-9839533548 | R5: 28 | S5: 33 | T5: EMP1061
A6: EMP1338 | B6: Sunita Sharma | C6: Sales | D6: Bengaluru | E6: Consultant | F6: FEMALE | G6: 29 | H6: MCA | I6: Terminated | J6: 2016-09-11 | K6: 6.8 | L6: 652601 | M6: 4.74 | N6: 5 | O6: Yes | P6: +91-9785809193 | Q6: sunita.sharma55@company.com | R6: 35 | S6: 63 | T6: EMP1067
A7: EMP1154 | B7: Rahul Patel | C7: marketing | D7: Delhi | E7: Senior Consultant | F7: Female | G7: 30 | H7: B.Tech | I7: on leave | J7: 2013-07-26 | K7: 24.3 | L7: 972149 | M7: 23.73 | N7: 3 | O7: No | P7: +91-8067614205 | Q7: rahul.patel10@company.com | R7: 51 | S7: 94 | T7: EMP1075
A8: EMP1294 | B8: Vishal Joshi | C8: Sales | D8: Delhi | E8: Executive | F8: Male | G8: 56 | H8: Diploma | I8: Terminated | J8: 2015-10-18 | K8: 15.9 | L8: 2357066 | M8: 15.05 | N8: 2 | O8: Yes | P8: 0000000000 | Q8: vishal.joshi28@company.com | R8: 45 | S8: 93 | T8: EMP1080
A9: EMP1254 | B9: Shruti Malhotra | C9: Information Technology | D9: Pune | E9: Analyst | F9: M | G9: 50 | H9: CA | I9: on leave | J9: 2012-04-18 | K9: 29.1 | L9: 2398965 | N9: 4 | O9: Yes | P9: +91-8995665351 | Q9: shruti.malhotra80@company.com | R9: 61 | S9: 32 | T9: EMP1088
A10: EMP1403 | B10: Ankit Nair | C10: Marketing | D10: Chennai | E10: Senior Manager | F10: male | G10: 25 | H10: Diploma | I10: Terminated | J10: 2018-01-11 | K10: 17.6 | L10: 1323161 | M10: 14.73 | N10: 2 | O10: No | P10: +91-8897937786 | Q10: ankit.nair26@company.com | R10: 38 | S10: 74 | T10: EMP1056
A11: EMP1315 | B11: Shweta Verma | C11: sales | D11: Bengaluru | E11: Intern | F11: male | G11: 45 | H11: B.Tech | I11: ACTIVE | J11: 2012-03-16 | K11: 17.3 | L11: 1327796 | N11: 4 | O11: No | P11: +91-9019427054 | Q11: shweta.verma44@company.com | R11: 14 | S11: 112
A12: EMP1191 | B12: Piyush Bose | C12: IT | D12: Chennai | E12: Director | F12: Male | G12: 25 | H12: BBA | I12: active | J12: 2024-09-08 | K12: 14.5 | L12: 1972456 | M12: 19.93 | N12: 3 | O12: No | P12: +91-9278231594 | Q12: piyush.bose2@company.com | R12: 40 | S12: 87 | T12: EMP1006
A13: EMP1358 | B13: Priya Sinha | C13: Legal | D13: New Delhi | E13: Intern | F13: female | G13: 49 | H13: B.Tech | I13: On Leave | J13: 2024-11-10 | K13: 16.8 | L13: 539572 | M13: 9.53 | N13: 4 | O13: N | P13: +91-9440843025 | Q13: priya.sinha34@company.com | R13: 30 | S13: 1 | T13: EMP1036
A14: EMP1397 | B14: Anjali Pandey | C14: Sales | D14: delhi | E14: Intern | F14: female | G14: 27 | H14: B.Com | I14: Contract | J14: 2018-09-28 | K14: 26.6 | L14: 395292 | M14: 8.07 | N14: 3 | O14: No | P14: +91-7752525490 | Q14: anjali.pandey92@company.com | R14: 3 | S14: 59 | T14: EMP1059
A15: EMP1100 | B15: Archana Kapoor | C15: Legal | D15: delhi | E15: Analyst | F15: Female | G15: 47 | H15: M.Tech | I15: On Leave | J15: 2016-08-18 | K15: 29.7 | L15: 1553428 | M15: 24.56 | N15: 4 | O15: No | P15: +91-7600406558 | Q15: archana.kapoor8@company.com | R15: 51 | S15: 80 | T15: EMP1083
A16: EMP1196 | B16: Pallavi Verma | C16: marketing | D16: Chennai | E16: VP | F16: Female | G16: 27 | H16: MCA | I16: Contract | J16: 2021-10-08 | K16: 4.6 | L16: 2137036 | M16: 0.41 | N16: 2 | O16: No | P16: +91-9146127091 | Q16: pallavi.verma58@company.com | R16: 43 | S16: 5 | T16: EMP1052
A17: EMP1173 | B17: REKHA SAXENA | C17: marketing | D17: Bengaluru | E17: VP | F17: M | G17: 32 | H17: BBA | I17: Contract | J17: 2020-08-03 | K17: 27.2 | L17: 528785 | M17: 11.27 | N17: 2 | O17: N | P17: +91-9989787464 | Q17: rekha.saxena51@company.com | R17: 75 | S17: 114 | T17: EMP1026
A18: EMP1015 | B18: Preeti Banerjee | C18: Finance | D18: Bengaluru | E18: Associate | F18: female | G18: 32 | H18: Diploma | I18: Contract | J18: 2023-04-22 | K18: 19.2 | L18: 1490286 | M18: 1.82 | N18: 4 | O18: Yes | P18: +91-8051590706 | Q18: preeti.banerjee79@company.com | R18: 80 | S18: 91 | T18: EMP1090
A19: EMP1273 | B19: Vikram Kapoor | C19: Finance | D19: Bangalore | E19: Lead | F19: Female | G19: 28 | H19: MCA | I19: active | J19: 2010-08-01 | K19: 5.4 | L19: 1667398 | M19: 17.73 | N19: 4 | O19: yes | P19: +91-7834957049 | Q19: vikram.kapoor2@company.com | R19: 59 | S19: 8 | T19: EMP1011
A20: EMP1147 | B20: Karan Patel | C20: Marketing | D20: hyderabad | E20: Senior Consultant | F20: female | G20: 44 | H20: MCA | I20: on leave | J20: 2016-11-24 | K20: 8.3 | L20: 340782 | M20: 6.73 | N20: 2 | O20: No | P20: +91-9046790105 | Q20: karan.patel28@company.com | R20: 24 | S20: 25 | T20: EMP1031
A21: EMP1107 | B21: Anjali Gupta | C21: Finance | D21: Chennai | E21: Manager | F21: MALE | G21: 32 | H21: B.Com | I21: on leave | J21: 2021-12-18 | K21: 6.1 | L21: 1688711 | M21: 3.84 | N21: 5 | O21: No | P21: +91-7213182609 | Q21: anjali.gupta71@company.com | R21: 54 | S21: 105 | T21: EMP1085
A22: EMP1018 | B22: TEJAS MENON | C22: HR | D22: New Delhi | E22: VP | F22: MALE | G22: 53 | H22: Diploma | I22: Inactive | J22: 2022-07-24 | K22: 12 | L22: 2128028 | M22: 3.39 | N22: 4 | O22: N | Q22: tejas.menon11@company.com | R22: 6 | S22: 41 | T22: EMP1028
A23: EMP1118 | B23: Smita Banerjee | C23: IT | D23: Bangalore | E23: Consultant | F23: MALE | G23: 52 | H23: B.Sc | I23: on leave | J23: 2024-06-25 | K23: 22.1 | L23: 458231 | M23: 2.57 | O23: No | P23: +91-7971803809 | Q23: smita.banerjee45@company.com | R23: 39 | S23: 105 | T23: EMP1006
A24: EMP1190 | B24: Anjali Mehta | C24: marketing | D24: New Delhi | E24: Analyst | F24: M | G24: 22 | H24: BBA | I24: Terminated | J24: 2015-03-09 | K24: 22.3 | L24: 1032383 | M24: 14.89 | N24: 4 | O24: Y | P24: +91-7142122736 | Q24: anjali.mehta11@company.com | R24: 63 | S24: 52 | T24: EMP1099
A25: EMP1352 | B25: Gaurav Reddy | C25: FINANCE | D25: pune | E25: Analyst | F25: Female | G25: 46 | H25: PhD | I25: on leave | J25: 2017-04-02 | K25: 15.8 | L25: 627758 | M25: 3.95 | N25: N/A | O25: No | P25: +91-8676868646 | Q25: gaurav.reddy9@company.com | R25: 68 | S25: 109 | T25: EMP1067
A26: EMP1293 | B26: Archana Sinha | C26: Human Resources | D26: pune | E26: Senior Consultant | F26: Male | G26: 26 | H26: B.Sc | I26: Contract | J26: 2011-03-28 | K26: 6.6 | L26: 820468 | M26: 14.06 | N26: N/A | O26: No | P26: N/A | Q26: archana.sinha84@company.com | R26: 4 | S26: 15 | T26: EMP1065
A27: EMP1362 | B27: Arjun Reddy | C27: Ops | D27: Hyderabad | E27: Senior Consultant | F27: F | G27: 24 | H27: M.Tech | I27: on leave | J27: 2011-04-19 | K27: 29.9 | L27: 929458 | M27: 15.18 | N27: 5 | O27: yes | P27: +91-9314847294 | Q27: arjun.reddy68@company.com | R27: 66 | S27: 34 | T27: EMP1025
A28: EMP1492 | B28: Amit Desai | C28: Operations | D28: Bengaluru | E28: Associate | F28: F | G28: 40 | H28: Diploma | I28: Terminated | J28: 2023-05-22 | K28: 27.9 | L28: 1982310 | M28: 3.69 | N28: 4 | O28: No | P28: +91-7158044711 | Q28: amit.desai76@company.com | R28: 16 | S28: 9 | T28: EMP1037
A29: EMP1263 | B29: Vivek Gupta | C29: Ops | D29: Mumbai | E29: Associate | F29: female | G29: 36 | H29: B.Tech | I29: Inactive | J29: 2015-12-13 | K29: 22.2 | L29: 1193967 | M29: 7.26 | N29: 3 | O29: Yes | Q29: vivek.gupta72@company.com | R29: 74 | S29: 46 | T29: EMP1006
A30: EMP1456 | B30: Sanjay Joshi | C30: Sales | D30: mumbai | E30: Manager | F30: F | G30: 45 | H30: Diploma | I30: Contract | J30: 2016-03-11 | K30: 19.1 | L30: 1872985 | M30: 1.4 | N30: 1 | O30: No | P30: +91-9429306031 | Q30: sanjay.joshi6@company.com | R30: 16 | S30: 118 | T30: EMP1009
A31: EMP1313 | B31: Nikhil Nair | C31: SALES | D31: MUMBAI | E31: VP | F31: F | G31: 49 | H31: MCA | I31: Contract | J31: 2020-04-13 | K31: 19.3 | L31: 2036208 | M31: 14.52 | N31: 4 | O31: NO | P31: +91-9286960285 | Q31: nikhil.nair30@company.com | R31: 73 | S31: 103 | T31: EMP1096
A32: EMP1290 | B32: Nikhil Desai | C32: Legal | D32: MUMBAI | E32: Manager | F32: MALE | G32: 52 | H32: MCA | I32: on leave | J32: 2021-04-23 | K32: 16.1 | L32: 1941494 | M32: 17.74 | N32: 3 | O32: No | P32: +91-9492728925 | Q32: nikhil.desai7@company.com | R32: 20 | S32: 56 | T32: EMP1090
A33: EMP1117 | B33: Komal Patel | C33: sales | D33: pune | E33: Consultant | F33: MALE | G33: 48 | H33: Diploma | I33: Terminated | J33: 2019-08-05 | K33: 6.4 | L33: 932410 | M33: 1.45 | N33: 3 | O33: NO | P33: +91-8428632583 | Q33: komal.patel23@company.com | R33: 26 | S33: 21 | T33: EMP1074
A34: EMP1202 | B34: Suresh Singh | C34: SALES | D34: Pune | E34: Director | F34: female | G34: 32 | H34: BBA | I34: ACTIVE | J34: 2013-10-16 | K34: 25.8 | L34: 1263441 | M34: 23.19 | N34: N/A | O34: No | P34: +91-8064427950 | Q34: suresh.singh75@company.com | R34: 73 | S34: 53
A35: EMP1409 | B35: Manish Bose | C35: Operations | D35: New Delhi | E35: Executive | F35: Male | G35: 48 | H35: B.Com | I35: active | J35: 2018-06-01 | K35: 25 | L35: 2339931 | M35: 1.68 | N35: 1 | O35: No | P35: +91-9314168714 | Q35: manish.bose74@company.com | R35: 11 | S35: 99 | T35: EMP1015
A36: EMP1291 | B36: Kavya Kumar | C36: Operations | D36: hyderabad | E36: Manager | F36: F | G36: 31 | H36: CA | I36: active | J36: 2015-08-06 | K36: 5.5 | L36: 2091433 | N36: 2 | O36: No | P36: +91-9548600919 | Q36: kavya.kumar20@company.com | R36: 30 | S36: 38 | T36: EMP1089
A37: EMP1007 | B37: Hemant Menon | C37: Ops | D37: Bangalore | E37: Senior Analyst | F37: Female | G37: 44 | H37: MBA | I37: on leave | J37: 2020-02-02 | K37: 2.1 | L37: 2258843 | M37: 10.55 | N37: 3 | O37: No | P37: +91-8067970820 | Q37: hemant.menon69@company.com | R37: 31 | S37: 9 | T37: EMP1057
A38: EMP1427 | B38: Manish Bose | C38: Sales | D38: New Delhi | E38: Senior Analyst | F38: Male | G38: 50 | H38: CA | I38: Contract | J38: 2020-10-13 | K38: 25.5 | L38: 1106309 | M38: 8.93 | N38: 3 | O38: No | P38: +91-8852482540 | Q38: manish.bose31@company.com | R38: 17 | S38: 105 | T38: EMP1090
A39: EMP1286 | B39: Varsha Pandey | C39: Finance | D39: hyderabad | E39: Senior Consultant | F39: Female | G39: 34 | H39: B.Sc | I39: Terminated | J39: 2010-03-16 | K39: 23.7 | L39: 2481266 | M39: 12.05 | N39: 5 | O39: Y | P39: +91-9004903816 | Q39: varsha.pandey58@company.com | R39: 31 | S39: 96 | T39: EMP1085
A40: EMP1218 | B40: Geeta Chatterjee | C40: FINANCE | D40: hyderabad | E40: Consultant | F40: Female | G40: 47 | H40: MBA | I40: ACTIVE | J40: 2015-04-11 | K40: 26.8 | L40: 726653 | M40: 14.84 | N40: 3 | O40: yes | P40: +91-9143661603 | Q40: geeta.chatterjee92@company.com | R40: 51 | S40: 85 | T40: EMP1078
...

Sheet DATA_DICTIONARY
A1: Column | B1: Description | C1: Notes
A2: Employee_ID | B2: Unique employee identifier | C2: Format: EMP + 4 digits. May contain duplicates (data entry error)
A3: Employee_Name | B3: Full name of employee | C3: Some names in UPPER CASE or reversed format (Last, First)
A4: Department | B4: Department name | C4: Inconsistent naming: 'IT' vs 'Information Technology', 'HR' vs 'Human Resources'
A5: Location | B5: City/office location | C5: Inconsistent: 'Mumbai' vs 'mumbai', 'Bangalore' vs 'Bengaluru'
A6: Job_Title | B6: Designation | C6: Standard titles
A7: Gender | B7: Employee gender | C7: Inconsistent: 'Male'/'male'/'M'/'MALE'
A8: Age | B8: Age in years | C8: Some erroneous values (negative, >100)
A9: Education | B9: Highest qualification | C9: Standard values
A10: Employment_Status | B10: Current status | C10: Inconsistent: 'Active'/'active'/'ACTIVE'
A11: Joining_Date | B11: Date of joining | C11: Multiple date formats used
A12: Experience_Years | B12: Total years of experience | C12: Some blank values
... A21: Manager_ID | B21: Reporting manager Employee ID | C21: Some blanks

Sheet WORKING_DATA
A1: Employee_ID | B1: Employee_Name | C1: Department | D1: Location | E1: Job_Title | F1: Gender | G1: Age | H1: Education | I1: Employment_Status | J1: Joining_Date | K1: Experience_Years | L1: Annual_Salary | M1: Bonus_Percent | N1: Performance_Rating | O1: Attrition | P1: Phone | Q1: Email | R1: Overtime_Hours | S1: Training_Hours | T1: Manager_ID | U1: Email_Valid | V1: Joining_Month_Num | W1: Joining_Month_Name | X1: Joining_Year | Y1: Tenure_Years | Z1: Age_Group | AA1: Salary_Band | AB1: Performance_Category | AC1: Bonus_Amount | AD1: Experience_Category
A2: EMP1493 | B2: Yash Gupta | C2: HR | D2: Bangalore | E2: Senior Manager | F2: Male | G2: 24 | H2: M.Tech | I2: Contract | J2: 45059 | K2: 2.4 | L2: 1939110 | M2: 0.1768 | N2: 4 | O2: Yes | P2: 8389763738 | Q2: yashgupta@companycom | R2: 72 | S2: 23 | T2: EMP1001 | U2: =IF(AND(ISNUMBER(FIND("@",Q2)),ISNUMBER(FIND(".",Q2))), "Valid","Invalid") -> Invalid | V2: =MONTH(J2) -> 5 | W2: =TEXT(J2, "MMM") -> May | X2: =YEAR(J2) -> 2023 | Y2: =DATEDIF(J2,TODAY(), "Y") -> 2 | Z2: {=_xlfn.IFS(G2<30,"20-29",G2<40,"30-39",G2<50,"40-49",G2>=50,"50+")} -> 20-29 | AA2: {=_xlfn.IFS(L2<500000,"Band 1: <5L", L2<1000000,"Band 2: 5-10L", L2<1500000,"Band 3: 10-15L", L2<2000000,"Band 4: 15-20L", L2>=2000000,"Band 5: 20L+")} -> Band 4: 15-20L | AB2: {=_xlfn.IFS(N2=1,"Poor", N2=2,"Below Average", N2=3,"Average", N2=4,"Good", N2=5,"Excellent")} -> Good | AC2: =L2*M2 -> 342834.65 | AD2: {=_xlfn.IFS(K2<2,"Junior (0-2 yrs)", K2<5,"Mid-Level (2-5 yrs)", K2<10,"Senior (5-10 yrs)", K2>=10,"Expert (10+ yrs)")} -> Mid-Level (2-5 yrs)
A3: EMP1262 | B3: Shruti Bhat | C3: Finance | D3: Delhi | E3: Intern | F3: Female | G3: 22 | H3: BBA | I3: On Leave | J3: 44940 | K3: 15.5 | L3: 906497 | M3: 0.173 | N3: 4 | O3: No | P3: 7293791975 | Q3: shrutibhat@company.com | R3: 42 | S3: 72 | T3: EMP1043 | U3: =IF(AND(ISNUMBER(FIND("@",Q3)),ISNUMBER(FIND(".",Q3))), "Valid","Invalid") -> Valid | V3: =MONTH(J3) -> 1 | W3: =TEXT(J3, "MMM") -> Jan | X3: =YEAR(J3) -> 2023 | Y3: =DATEDIF(J3,TODAY(), "Y") -> 3 | Z3: {=_xlfn.IFS(G3<30,"20-29",G3<40,"30-39",G3<50,"40-49",G3>=50,"50+")} -> 20-29 | AA3: {=_xlfn.IFS(L3<500000,"Band 1: <5L", L3<1000000,"Band 2: 5-10L", L3<1500000,"Band 3: 10-15L", L3<2000000,"Band 4: 15-20L", L3>=2000000,"Band 5: 20L+")} -> Band 2: 5-10L | AB3: {=_xlfn.IFS(N3=1,"Poor", N3=2,"Below Average", N3=3,"Average", N3=4,"Good", N3=5,"Excellent")} -> Good | AC3: =L3*M3 -> 156823.98 | AD3: {=_xlfn.IFS(K3<2,"Junior (0-2 yrs)", K3<5,"Mid-Level (2-5 yrs)", K3<10,"Senior (5-10 yrs)", K3>=10,"Expert (10+ yrs)")} -> Expert (10+ yrs)
A4: EMP1338 | B4: Sunita Sharma | C4: Sales | D4: Bangalore | E4: Consultant | F4: Female | G4: 29 | H4: MCA | I4: Terminated | J4: 42624 | K4: 6.8 | L4: 652601 | M4: 0.0474 | N4: 5 | O4: Yes | P4: 9785809193 | Q4: sunitasharma@company.com | R4: 35 | S4: 63 | T4: EMP1067 | U4: =IF(AND(ISNUMBER(FIND("@",Q4)),ISNUMBER(FIND(".",Q4))), "Valid","Invalid") -> Valid | V4: =MONTH(J4) -> 9 | W4: =TEXT(J4, "MMM") -> Sep | X4: =YEAR(J4) -> 2016 | Y4: =DATEDIF(J4,TODAY(), "Y") -> 9 | Z4: {=_xlfn.IFS(G4<30,"20-29",G4<40,"30-39",G4<50,"40-49",G4>=50,"50+")} -> 20-29 | AA4: {=_xlfn.IFS(L4<500000,"Band 1: <5L", L4<1000000,"Band 2: 5-10L", L4<1500000,"Band 3: 10-15L", L4<2000000,"Band 4: 15-20L", L4>=2000000,"Band 5: 20L+")} -> Band 2: 5-10L | AB4: {=_xlfn.IFS(N4=1,"Poor", N4=2,"Below Average", N4=3,"Average", N4=4,"Good", N4=5,"Excellent")} -> Excellent | AC4: =L4*M4 -> 30933.287 | AD4: {=_xlfn.IFS(K4<2,"Junior (0-2 yrs)", K4<5,"Mid-Level (2-5 yrs)", K4<10,"Senior (5-10 yrs)", K4>=10,"Expert (10+ yrs)")} -> Senior (5-10 yrs)
A5: EMP1154 | B5: Rahul Patel | C5: Marketing | D5: Delhi | E5: Senior Consultant | F5: Female | G5: 30 | H5: B.Tech | I5: On Leave | J5: 41481 | K5: 24.3 | L5: 972149 | M5: 0.2373 | N5: 3 | O5: No | P5: 8067614205 | Q5: rahulpatel@company.com | R5: 51 | S5: 94 | T5: EMP1075 | U5: =IF(AND(ISNUMBER(FIND("@",Q5)),ISNUMBER(FIND(".",Q5))), "Valid","Invalid") -> Valid | V5: =MONTH(J5) -> 7 | W5: =TEXT(J5, "MMM") -> Jul | X5: =YEAR(J5) -> 2013 | Y5: =DATEDIF(J5,TODAY(), "Y") -> 12 | Z5: {=_xlfn.IFS(G5<30,"20-29",G5<40,"30-39",G5<50,"40-49",G5>=50,"50+")} -> 30-39 | AA5: {=_xlfn.IFS(L5<500000,"Band 1: <5L", L5<1000000,"Band 2: 5-10L", L5<1500000,"Band 3: 10-15L", L5<2000000,"Band 4: 15-20L", L5>=2000000,"Band 5: 20L+")} -> Band 2: 5-10L | AB5: {=_xlfn.IFS(N5=1,"Poor", N5=2,"Below Average", N5=3,"Average", N5=4,"Good", N5=5,"Excellent")} -> Average | AC5: =L5*M5 -> 230690.96 | AD5: {=_xlfn.IFS(K5<2,"Junior (0-2 yrs)", K5<5,"Mid-Level (2-5 yrs)", K5<10,"Senior (5-10 yrs)", K5>=10,"Expert (10+ yrs)")} -> Expert (10+ yrs)
A6: EMP1403 | B6: Ankit Nair | C6: Marketing | D6: Chennai | E6: Senior Manager | F6: Male | G6: 25 | H6: Diploma | I6: Terminated | J6: 43111 | K6: 17.6 | L6: 1323161 | M6: 0.1473 | N6: 2 | O6: No | P6: 8897937786 | Q6: ankitnair@company.com | R6: 38 | S6: 74 | T6: EMP1056 | U6: =IF(AND(ISNUMBER(FIND("@",Q6)),ISNUMBER(FIND(".",Q6))), "Valid","Invalid") -> Valid | V6: =MONTH(J6) -> 1 | W6: =TEXT(J6, "MMM") -> Jan | X6: =YEAR(J6) -> 2018 | Y6: =DATEDIF(J6,TODAY(), "Y") -> 8 | Z6: {=_xlfn.IFS(G6<30,"20-29",G6<40,"30-39",G6<50,"40-49",G6>=50,"50+")} -> 20-29 | AA6: {=_xlfn.IFS(L6<500000,"Band 1: <5L", L6<1000000,"Band 2: 5-10L", L6<1500000,"Band 3: 10-15L", L6<2000000,"Band 4: 15-20L", L6>=2000000,"Band 5: 20L+")} -> Band 3: 10-15L | AB6: {=_xlfn.IFS(N6=1,"Poor", N6=2,"Below Average", N6=3,"Average", N6=4,"Good", N6=5,"Excellent")} -> Below Average | AC6: =L6*M6 -> 194901.62 | AD6: {=_xlfn.IFS(K6<2,"Junior (0-2 yrs)", K6<5,"Mid-Level (2-5 yrs)", K6<10,"Senior (5-10 yrs)", K6>=10,"Expert (10+ yrs)")} -> Expert (10+ yrs)
A7: EMP1191 | B7: Piyush Bose | C7: IT | D7: Chennai | E7: Director | F7: Male | G7: 25 | H7: BBA | I7: Active | J7: 45543 | K7: 14.5 | L7: 1972456 | M7: 0.1993 | N7: 3 | O7: No | P7: 9278231594 | Q7: piyushboseat-company.com | R7: 40 | S7: 87 | T7: EMP1006 | U7: =IF(AND(ISNUMBER(FIND("@",Q7)),ISNUMBER(FIND(".",Q7))), "Valid","Invalid") -> Invalid | V7: =MONTH(J7) -> 9 | W7: =TEXT(J7, "MMM") -> Sep | X7: =YEAR(J7) -> 2024 | Y7: =DATEDIF(J7,TODAY(), "Y") -> 1 | Z7: {=_xlfn.IFS(G7<30,"20-29",G7<40,"30-39",G7<50,"40-49",G7>=50,"50+")} -> 20-29 | AA7: {=_xlfn.IFS(L7<500000,"Band 1: <5L", L7<1000000,"Band 2: 5-10L", L7<1500000,"Band 3: 10-15L", L7<2000000,"Band 4: 15-20L", L7>=2000000,"Band 5: 20L+")} -> Band 4: 15-20L | AB7: {=_xlfn.IFS(N7=1,"Poor", N7=2,"Below Average", N7=3,"Average", N7=4,"Good", N7=5,"Excellent")} -> Average | AC7: =L7*M7 -> 393110.48 | AD7: {=_xlfn.IFS(K7<2,"Junior (0-2 yrs)", K7<5,"Mid-Level (2-5 yrs)", K7<10,"Senior (5-10 yrs)", K7>=10,"Expert (10+ yrs)")} -> Expert (10+ yrs)
A8: EMP1358 | B8: Priya Sinha | C8: Legal | D8: Delhi | E8: Intern | F8: Female | G8: 49 | H8: B.Tech | I8: On Leave | J8: 45606 | K8: 16.8 | L8: 539572 | M8: 0.0953 | N8: 4 | O8: No | P8: 9440843025 | Q8: priyasinhaat-company.com | R8: 30 | S8: 1 | T8: EMP1036 | U8: =IF(AND(ISNUMBER(FIND("@",Q8)),ISNUMBER(FIND(".",Q8))), "Valid","Invalid") -> Invalid | V8: =MONTH(J8) -> 11 | W8: =TEXT(J8, "MMM") -> Nov | X8: =YEAR(J8) -> 2024 | Y8: =DATEDIF(J8,TODAY(), "Y") -> 1 | Z8: {=_xlfn.IFS(G8<30,"20-29",G8<40,"30-39",G8<50,"40-49",G8>=50,"50+")} -> 40-49 | AA8: {=_xlfn.IFS(L8<500000,"Band 1: <5L", L8<1000000,"Band 2: 5-10L", L8<1500000,"Band 3: 10-15L", L8<2000000,"Band 4: 15-20L", L8>=2000000,"Band 5: 20L+")} -> Band 2: 5-10L | AB8: {=_xlfn.IFS(N8=1,"Poor", N8=2,"Below Average", N8=3,"Average", N8=4,"Good", N8=5,"Excellent")} -> Good | AC8: =L8*M8 -> 51421.212 | AD8: {=_xlfn.IFS(K8<2,"Junior (0-2 yrs)", K8<5,"Mid-Level (2-5 yrs)", K8<10,"Senior (5-10 yrs)", K8>=10,"Expert (10+ yrs)")} -> Expert (10+ yrs)
A9: EMP1397 | B9: Anjali Pandey | C9: Sales | D9: Delhi | E9: Intern | F9: Female | G9: 27 | H9: B.Com | I9: Contract | J9: 43371 | K9: 26.6 | L9: 395292 | M9: 0.0807 | N9: 3 | O9: No | P9: 7752525490 | Q9: anjalipandeyat-company.com | R9: 3 | S9: 59 | T9: EMP1059 | U9: =IF(AND(ISNUMBER(FIND("@",Q9)),ISNUMBER(FIND(".",Q9))), "Valid","Invalid") -> Invalid | V9: =MONTH(J9) -> 9 | W9: =TEXT(J9, "MMM") -> Sep | X9: =YEAR(J9) -> 2018 | Y9: =DATEDIF(J9,TODAY(), "Y") -> 7 | Z9: {=_xlfn.IFS(G9<30,"20-29",G9<40,"30-39",G9<50,"40-49",G9>=50,"50+")} -> 20-29 | AA9: {=_xlfn.IFS(L9<500000,"Band 1: <5L", L9<1000000,"Band 2: 5-10L", L9<1500000,"Band 3: 10-15L", L9<2000000,"Band 4: 15-20L", L9>=2000000,"Band 5: 20L+")} -> Band 1: <5L | AB9: {=_xlfn.IFS(N9=1,"Poor", N9=2,"Below Average", N9=3,"Average", N9=4,"Good", N9=5,"Excellent")} -> Average | AC9: =L9*M9 -> 31900.064 | AD9: {=_xlfn.IFS(K9<2,"Junior (0-2 yrs)", K9<5,"Mid-Level (2-5 yrs)", K9<10,"Senior (5-10 yrs)", K9>=10,"Expert (10+ yrs)")} -> Expert (10+ yrs)
A10: EMP1100 | B10: Archana Kapoor | C10: Legal | D10: Delhi | E10: Analyst | F10: Female | G10: 47 | H10: M.Tech | I10: On Leave | J10: 42600 | K10: 29.7 | L10: 1553428 | M10: 0.2456 | N10: 4 | O10: No | P10: 7600406558 | Q10: archanakapoorat-company.com | R10: 51 | S10: 80 | T10: EMP1083 | U10: =IF(AND(ISNUMBER(FIND("@",Q10)),ISNUMBER(FIND(".",Q10))), "Valid","Invalid") -> Invalid | V10: =MONTH(J10) -> 8 | W10: =TEXT(J10, "MMM") -> Aug | X10: =YEAR(J10) -> 2016 | Y10: =DATEDIF(J10,TODAY(), "Y") -> 9 | Z10: {=_xlfn.IFS(G10<30,"20-29",G10<40,"30-39",G10<50,"40-49",G10>=50,"50+")} -> 40-49 | AA10: {=_xlfn.IFS(L10<500000,"Band 1: <5L", L10<1000000,"Band 2: 5-10L", L10<1500000,"Band 3: 10-15L", L10<2000000,"Band 4: 15-20L", L10>=2000000,"Band 5: 20L+")} -> Band 4: 15-20L | AB10: {=_xlfn.IFS(N10=1,"Poor", N10=2,"Below Average", N10=3,"Average", N10=4,"Good", N10=5,"Excellent")} -> Good | AC10: =L10*M10 -> 381521.92 | AD10: {=_xlfn.IFS(K10<2,"Junior (0-2 yrs)", K10<5,"Mid-Level (2-5 yrs)", K10<10,"Senior (5-10 yrs)", K10>=10,"Expert (10+ yrs)")} -> Expert (10+ yrs)
A11: EMP1196 | B11: Pallavi Verma | C11: Marketing | D11: Chennai | E11: VP | F11: Female | G11: 27 | H11: MCA | I11: Contract | J11: 44477 | K11: 4.6 | L11: 2137036 | M11: 0.0041 | N11: 2 | O11: No | P11: 9146127091 | Q11: pallaviverma@company.com | R11: 43 | S11: 5 | T11: EMP1052 | U11: =IF(AND(ISNUMBER(FIND("@",Q11)),ISNUMBER(FIND(".",Q11))), "Valid","Invalid") -> Valid | V11: =MONTH(J11) -> 10 | W11: =TEXT(J11, "MMM") -> Oct | X11: =YEAR(J11) -> 2021 | Y11: =DATEDIF(J11,TODAY(), "Y") -> 4 | Z11: {=_xlfn.IFS(G11<30,"20-29",G11<40,"30-39",G11<50,"40-49",G11>=50,"50+")} -> 20-29 | AA11: {=_xlfn.IFS(L11<500000,"Band 1: <5L", L11<1000000,"Band 2: 5-10L", L11<1500000,"Band 3: 10-15L", L11<2000000,"Band 4: 15-20L", L11>=2000000,"Band 5: 20L+")} -> Band 5: 20L+ | AB11: {=_xlfn.IFS(N11=1,"Poor", N11=2,"Below Average", N11=3,"Average", N11=4,"Good", N11=5,"Excellent")} -> Below Average | AC11: =L11*M11 -> 8761.8476 | AD11: {=_xlfn.IFS(K11<2,"Junior (0-2 yrs)", K11<5,"Mid-Level (2-5 yrs)", K11<10,"Senior (5-10 yrs)", K11>=10,"Expert (10+ yrs)")} -> Mid-Level (2-5 yrs)
A12: EMP1173 | B12: Rekha Saxena | C12: Marketing | D12: Bangalore | E12: VP | F12: Male | G12: 32 | H12: BBA | I12: Contract | J12: 44046 | K12: 27.2 | L12: 528785 | M12: 0.1127 | N12: 2 | O12: No | P12: 9989787464 | Q12: rekhasaxena@companycom | R12: 75 | S12: 114 | T12: EMP1026 | U12: =IF(AND(ISNUMBER(FIND("@",Q12)),ISNUMBER(FIND(".",Q12))), "Valid","Invalid") -> Invalid | V12: =MONTH(J12) -> 8 | W12: =TEXT(J12, "MMM") -> Aug | X12: =YEAR(J12) -> 2020 | Y12: =DATEDIF(J12,TODAY(), "Y") -> 5 | Z12: {=_xlfn.IFS(G12<30,"20-29",G12<40,"30-39",G12<50,"40-49",G12>=50,"50+")} -> 30-39 | AA12: {=_xlfn.IFS(L12<500000,"Band 1: <5L", L12<1000000,"Band 2: 5-10L", L12<1500000,"Band 3: 10-15L", L12<2000000,"Band 4: 15-20L", L12>=2000000,"Band 5: 20L+")} -> Band 2: 5-10L | AB12: {=_xlfn.IFS(N12=1,"Poor", N12=2,"Below Average", N12=3,"Average", N12=4,"Good", N12=5,"Excellent")} -> Below Average | AC12: =L12*M12 -> 59594.069 | AD12: {=_xlfn.IFS(K12<2,"Junior (0-2 yrs)", K12<5,"Mid-Level (2-5 yrs)", K12<10,"Senior (5-10 yrs)", K12>=10,"Expert (10+ yrs)")} -> Expert (10+ yrs)
A13: EMP1015 | B13: Preeti Banerjee | C13: Finance | D13: Bangalore | E13: Associate | F13: Female | G13: 32 | H13: Diploma | I13: Contract | J13: 45038 | K13: 19.2 | L13: 1490286 | M13: 0.0182 | N13: 4 | O13: Yes | P13: 8051590706 | Q13: preetibanerjee@companycom | R13: 80 | S13: 91 | T13: EMP1090 | U13: =IF(AND(ISNUMBER(FIND("@",Q13)),ISNUMBER(FIND(".",Q13))), "Valid","Invalid") -> Invalid | V13: =MONTH(J13) -> 4 | W13: =TEXT(J13, "MMM") -> Apr | X13: =YEAR(J13) -> 2023 | Y13: =DATEDIF(J13,TODAY(), "Y") -> 2 | Z13: {=_xlfn.IFS(G13<30,"20-29",G13<40,"30-39",G13<50,"40-49",G13>=50,"50+")} -> 30-39 | AA13: {=_xlfn.IFS(L13<500000,"Band 1: <5L", L13<1000000,"Band 2: 5-10L", L13<1500000,"Band 3: 10-15L", L13<2000000,"Band 4: 15-20L", L13>=2000000,"Band 5: 20L+")} -> Band 3: 10-15L | AB13: {=_xlfn.IFS(N13=1,"Poor", N13=2,"Below Average", N13=3,"Average", N13=4,"Good", N13=5,"Excellent")} -> Good | AC13: =L13*M13 -> 27123.205 | AD13: {=_xlfn.IFS(K13<2,"Junior (0-2 yrs)", K13<5,"Mid-Level (2-5 yrs)", K13<10,"Senior (5-10 yrs)", K13>=10,"Expert (10+ yrs)")} -> Expert (10+ yrs)
... A323: EMP1079 | B323: Archana Banerjee | C323: HR | D323: Delhi | E323: Senior Manager | F323: Female | G323: 50 | H323: B.Tech | I323: Terminated | J323: 43360 | K323: 3.1 | L323: 1431482 | M323: 0.0031 | N323: 1 | O323: Yes | P323: 7399707954 | Q323: archanabanerjee@company.com | R323: 10 | S323: 71 | T323: EMP1032 | U323: =IF(AND(ISNUMBER(FIND("@",Q323)),ISNUMBER(FIND(".",Q323))), "Valid","Invalid") -> Valid | V323: =MONTH(J323) -> 9 | W323: =TEXT(J323, "MMM") -> Sep | X323: =YEAR(J323) -> 2018 | Y323: =DATEDIF(J323,TODAY(), "Y") -> 7 | Z323: {=_xlfn.IFS(G323<30,"20-29",G323<40,"30-39",G323<50,"40-49",G323>=50,"50+")} -> 50+ | AA323: {=_xlfn.IFS(L323<500000,"Band 1: <5L", L323<1000000,"Band 2: 5-10L", L323<1500000,"Band 3: 10-15L", L323<2000000,"Band 4: 15-20L", L323>=2000000,"Band 5: 20L+")} -> Band 3: 10-15L | AB323: {=_xlfn.IFS(N323=1,"Poor", N323=2,"Below Average", N323=3,"Average", N323=4,"Good", N323=5,"Excellent")} -> Poor | AC323: =L323*M323 -> 4437.5942 | AD323: {=_xlfn.IFS(K323<2,"Junior (0-2 yrs)", K323<5,"Mid-Level (2-5 yrs)", K323<10,"Senior (5-10 yrs)", K323>=10,"Expert (10+ yrs)")} -> Mid-Level (2-5 yrs)

Sheet HR_SUMMARY
A1: HEADCOUNT OVERVIEW | D1: DEPARTMENT | E1: Headcount | F1: Avg Salary | G1: Attrition Count | I1: GENDER SPLIT
A2: Total Employees | B2: =COUNTA(WORKING_DATA!A2:A2000) -> 322 | D2: Finance | E2: =COUNTIF(WORKING_DATA!$C:$C,$D2) -> 42 | F2: =AVERAGEIF(WORKING_DATA!$C:$C,$D2,WORKING_DATA!$L:$L) -> 1305434.8 | G2: =COUNTIFS(WORKING_DATA!$C:$C,$D2,WORKING_DATA!$O:$O,"Yes") -> 16 | I2: Male | J2: =COUNTIF(Dataset[Gender],HR_SUMMARY!$I2) -> 151 | K2: =IFERROR((J2/$B$2)*100,0)/100 -> 0.4689441
A3: Active Employees | B3: =COUNTIF(WORKING_DATA!I:I,"Active") -> 133 | D3: HR | E3: =COUNTIF(WORKING_DATA!$C:$C,$D3) -> 46 | F3: =AVERAGEIF(WORKING_DATA!$C:$C,$D3,WORKING_DATA!$L:$L) -> 1371317 | G3: =COUNTIFS(WORKING_DATA!$C:$C,$D3,WORKING_DATA!$O:$O,"Yes") -> 17 | I3: Female | J3: =COUNTIF(Dataset[Gender],HR_SUMMARY!$I3) -> 171 | K3: =IFERROR((J3/$B$2)*100,0)/100 -> 0.5310559
A4: Attrition Count | B4: =COUNTIF(WORKING_DATA!O:O,"Yes") -> 100 | D4: Legal | E4: =COUNTIF(WORKING_DATA!$C:$C,$D4) -> 25 | F4: =AVERAGEIF(WORKING_DATA!$C:$C,$D4,WORKING_DATA!$L:$L) -> 1484572.2 | G4: =COUNTIFS(WORKING_DATA!$C:$C,$D4,WORKING_DATA!$O:$O,"Yes") -> 5
A5: Attrition Rate % | B5: =IFERROR(B4/B2*100,0) -> 31.055901 | D5: Marketing | E5: =COUNTIF(WORKING_DATA!$C:$C,$D5) -> 37 | F5: =AVERAGEIF(WORKING_DATA!$C:$C,$D5,WORKING_DATA!$L:$L) -> 1456657.5 | G5: =COUNTIFS(WORKING_DATA!$C:$C,$D5,WORKING_DATA!$O:$O,"Yes") -> 9
A6: Avg Age | B6: =AVERAGEIF(WORKING_DATA!G:G,">"&0) -> 40.130435 | D6: Operations | E6: =COUNTIF(WORKING_DATA!$C:$C,$D6) -> 55 | F6: =AVERAGEIF(WORKING_DATA!$C:$C,$D6,WORKING_DATA!$L:$L) -> 1385380.1 | G6: =COUNTIFS(WORKING_DATA!$C:$C,$D6,WORKING_DATA!$O:$O,"Yes") -> 14
A7: Avg Tenure (Years) | B7: =AVERAGE(WORKING_DATA!Y:Y) -> 8.1459627 | D7: Sales | E7: =COUNTIF(WORKING_DATA!$C:$C,$D7) -> 75 | F7: =AVERAGEIF(WORKING_DATA!$C:$C,$D7,WORKING_DATA!$L:$L) -> 1514842.2 | G7: =COUNTIFS(WORKING_DATA!$C:$C,$D7,WORKING_DATA!$O:$O,"Yes") -> 27
A8: Avg Salary (₹) | B8: =AVERAGEIF(WORKING_DATA!L:L,">"&0) -> 1419754.4

Sheet PIVOT_TABLES
B2: Department | C2: Count of Employees | E2: Count Employees | F2: Attrition | J2: Performance Category | K2: Count of Employees | M2: Count of Employees | N2: Gender | R2: Count of Employees | S2: Salary Band
B3: Finance | C3: 42 | E3: Department | F3: No | G3: Yes | H3: Grand Total | J3: Average | K3: 103 | M3: Location | N3: Female | O3: Male | P3: Grand Total | R3: Experience Category | S3: Band 1: <5L | T3: Band 2: 5-10L | U3: Band 3: 10-15L | V3: Band 4: 15-20L | W3: Band 5: 20L+ | X3: Grand Total
B4: HR | C4: 46 | E4: Finance | F4: 26 | G4: 16 | H4: 42 | J4: Below Average | K4: 30 | M4: Bangalore | N4: 48 | O4: 35 | P4: 83 | R4: Expert (10+ yrs) | S4: 21 | T4: 51 | U4: 49 | V4: 50 | W4: 48 | X4: 219
B5: IT | C5: 42 | E5: HR | F5: 29 | G5: 17 | H5: 46 | J5: Excellent | K5: 73 | M5: Chennai | N5: 14 | O5: 13 | P5: 27 | R5: Junior (0-2 yrs) | T5: 1 | U5: 5 | V5: 1 | W5: 3 | X5: 10
B6: Legal | C6: 25 | E6: IT | F6: 30 | G6: 12 | H6: 42 | J6: Good | K6: 88 | M6: Delhi | N6: 30 | O6: 24 | P6: 54 | R6: Mid-Level (2-5 yrs) | S6: 1 | T6: 7 | U6: 6 | V6: 7 | W6: 12 | X6: 33
B7: Marketing | C7: 37 | E7: Legal | F7: 20 | G7: 5 | H7: 25 | J7: Poor | K7: 28 | M7: Hyderabad | N7: 21 | O7: 19 | P7: 40 | R7: Senior (5-10 yrs) | S7: 6 | T7: 17 | U7: 12 | V7: 10 | W7: 15 | X7: 60
B8: Operations | C8: 55 | E8: Marketing | F8: 28 | G8: 9 | H8: 37 | J8: Grand Total | K8: 322 | M8: Mumbai | N8: 38 | O8: 35 | P8: 73 | R8: Grand Total | S8: 28 | T8: 76 | U8: 72 | V8: 68 | W8: 78 | X8: 322
B9: Sales | C9: 75 | E9: Operations | F9: 41 | G9: 14 | H9: 55 | M9: Pune | N9: 20 | O9: 25 | P9: 45
B10: Grand Total | C10: 322 | E10: Sales | F10: 48 | G10: 27 | H10: 75 | M10: Grand Total | N10: 171 | O10: 151 | P10: 322
E11: Grand Total | F11: 222 | G11: 100 | H11: 322

Sheet CHARTS

Sheet HR_DASHBOARD
A1: 🏢 HUMAN RESOURCES ANALYTICS DASHBOARD
A4: FY 2024-25 | Confidential | HR Department
B6: 👥 TOTAL EMPLOYEES | G6: ✅ ACTIVE EMPLOYEES | L6: ⚠️ ATTRITION RATE | Q6: 💰 AVG ANNUAL SALARY | V6: 📅 AVG TENURE | AA6: 🎂 AVG AGE
B7: {=Total_Employees} -> 322 | G7: {=Active_Employees} -> 133 | L7: {=ROUND(Attrition_Rate,1)&"%"} -> 31.1% | Q7: ="₹"&TEXT(HR_SUMMARY!B8,"#,##0") -> ₹14,19,754 | V7: =ROUND(HR_SUMMARY!B7,1)&" Yrs" -> 8.1 Yrs | AA7: =ROUND(HR_SUMMARY!B6,1)&" Yrs" -> 40.1 Yrs
AB15: 🔽 FILTER BY DEPARTMENT
AB21: 🔽 FILTER BY LOCATION
AB35: 🔽 FILTER BY GENDER
